Workbook
Name ExternalData_1: Query1!$A$1:$B$14
Name ExternalData_1: Currency!$B$1:$D$52

Sheet Query1
A1: Name | B1: RowCount
A2: TableIndex | B2: 12
A3: tBusinesses | B3: 170
A4: tCDNPlaces | B4: 98
A5: tCourses | B5: 42
A6: tCurrency | B6: 51
A7: tGlobalPlaces | B7: 25
A8: tImprovementLevy | B8: 13
A9: tNames | B9: 390
A10: tObjectUserCosts | B10: 103
A11: tSandwiches | B11: 51
A12: tSummerJobs | B12: 50
A13: tTheaters | B13: 50
A14: tVehicles | B14: 100

Sheet ReadMe
A3: Insert a Name | B3: INDEX(WorksheetMergeMasterSourceFile.xlsx!tNames[#Data], RANDBETWEEN(1, ROWS(WorksheetMergeMasterSourceFile.xlsx!tNames[#Data])), 4)

Sheet 179Products

Sheet Names
A1: Code | B1: Gender | C1: FullName | D1: FirstName | E1: LastName | F1: Title | G1: SheHeThey | H1: HerHimThem | I1: HerHisTheir
A2: 1 | B2: M | C2: Evan Lee | D2: Evan | E2: Lee | F2: =IF(Names!$B2="M","Mr.",IF(Names!$B2="F","Ms.","Mx.")) -> Mr. | G2: =IF(Names!$B2="M","he",IF(Names!$B2="F","she","they")) -> he | H2: =IF(Names!$B2="M","him",IF(Names!$B2="F","her","them")) -> him | I2: =IF(Names!$B2="M","his",IF(Names!$B2="F","her","their")) -> his
A3: 2 | B3: M | C3: Benjamin Hennessy | D3: Benjamin | E3: Hennessy | F3: =IF(Names!$B3="M","Mr.",IF(Names!$B3="F","Ms.","Mx.")) -> Mr. | G3: =IF(Names!$B3="M","he",IF(Names!$B3="F","she","they")) -> he | H3: =IF(Names!$B3="M","him",IF(Names!$B3="F","her","them")) -> him | I3: =IF(Names!$B3="M","his",IF(Names!$B3="F","her","their")) -> his
A4: 3 | B4: M | C4: Zander Barry | D4: Zander | E4: Barry | F4: =IF(Names!$B4="M","Mr.",IF(Names!$B4="F","Ms.","Mx.")) -> Mr. | G4: =IF(Names!$B4="M","he",IF(Names!$B4="F","she","they")) -> he | H4: =IF(Names!$B4="M","him",IF(Names!$B4="F","her","them")) -> him | I4: =IF(Names!$B4="M","his",IF(Names!$B4="F","her","their")) -> his
A5: 4 | B5: M | C5: Mateo Stephenson | D5: Mateo | E5: Stephenson | F5: =IF(Names!$B5="M","Mr.",IF(Names!$B5="F","Ms.","Mx.")) -> Mr. | G5: =IF(Names!$B5="M","he",IF(Names!$B5="F","she","they")) -> he | H5: =IF(Names!$B5="M","him",IF(Names!$B5="F","her","them")) -> him | I5: =IF(Names!$B5="M","his",IF(Names!$B5="F","her","their")) -> his
A6: 5 | B6: M | C6: Nathaniel Snow | D6: Nathaniel | E6: Snow | F6: =IF(Names!$B6="M","Mr.",IF(Names!$B6="F","Ms.","Mx.")) -> Mr. | G6: =IF(Names!$B6="M","he",IF(Names!$B6="F","she","they")) -> he | H6: =IF(Names!$B6="M","him",IF(Names!$B6="F","her","them")) -> him | I6: =IF(Names!$B6="M","his",IF(Names!$B6="F","her","their")) -> his
A7: 6 | B7: M | C7: Ethan Eaton | D7: Ethan | E7: Eaton | F7: =IF(Names!$B7="M","Mr.",IF(Names!$B7="F","Ms.","Mx.")) -> Mr. | G7: =IF(Names!$B7="M","he",IF(Names!$B7="F","she","they")) -> he | H7: =IF(Names!$B7="M","him",IF(Names!$B7="F","her","them")) -> him | I7: =IF(Names!$B7="M","his",IF(Names!$B7="F","her","their")) -> his
A8: 7 | B8: M | C8: Ryker Macdonald | D8: Ryker | E8: Macdonald | F8: =IF(Names!$B8="M","Mr.",IF(Names!$B8="F","Ms.","Mx.")) -> Mr. | G8: =IF(Names!$B8="M","he",IF(Names!$B8="F","she","they")) -> he | H8: =IF(Names!$B8="M","him",IF(Names!$B8="F","her","them")) -> him | I8: =IF(Names!$B8="M","his",IF(Names!$B8="F","her","their")) -> his
A9: 8 | B9: N | C9: Soren Beech | D9: Soren | E9: Beech | F9: =IF(Names!$B9="M","Mr.",IF(Names!$B9="F","Ms.","Mx.")) -> Mx. | G9: =IF(Names!$B9="M","he",IF(Names!$B9="F","she","they")) -> they | H9: =IF(Names!$B9="M","him",IF(Names!$B9="F","her","them")) -> them | I9: =IF(Names!$B9="M","his",IF(Names!$B9="F","her","their")) -> their
A10: 9 | B10: M | C10: Lane Arbour | D10: Lane | E10: Arbour | F10: =IF(Names!$B10="M","Mr.",IF(Names!$B10="F","Ms.","Mx.")) -> Mr. | G10: =IF(Names!$B10="M","he",IF(Names!$B10="F","she","they")) -> he | H10: =IF(Names!$B10="M","him",IF(Names!$B10="F","her","them")) -> him | I10: =IF(Names!$B10="M","his",IF(Names!$B10="F","her","their")) -> his
A11: 10 | B11: M | C11: Jordan George | D11: Jordan | E11: George | F11: =IF(Names!$B11="M","Mr.",IF(Names!$B11="F","Ms.","Mx.")) -> Mr. | G11: =IF(Names!$B11="M","he",IF(Names!$B11="F","she","they")) -> he | H11: =IF(Names!$B11="M","him",IF(Names!$B11="F","her","them")) -> him | I11: =IF(Names!$B11="M","his",IF(Names!$B11="F","her","their")) -> his
A12: 11 | B12: M | C12: Atlas Kane | D12: Atlas | E12: Kane | F12: =IF(Names!$B12="M","Mr.",IF(Names!$B12="F","Ms.","Mx.")) -> Mr. | G12: =IF(Names!$B12="M","he",IF(Names!$B12="F","she","they")) -> he | H12: =IF(Names!$B12="M","him",IF(Names!$B12="F","her","them")) -> him | I12: =IF(Names!$B12="M","his",IF(Names!$B12="F","her","their")) -> his
A13: 12 | B13: M | C13: Evan Daniel | D13: Evan | E13: Daniel | F13: =IF(Names!$B13="M","Mr.",IF(Names!$B13="F","Ms.","Mx.")) -> Mr. | G13: =IF(Names!$B13="M","he",IF(Names!$B13="F","she","they")) -> he | H13: =IF(Names!$B13="M","him",IF(Names!$B13="F","her","them")) -> him | I13: =IF(Names!$B13="M","his",IF(Names!$B13="F","her","their")) -> his
... A49: 48 | B49: M | C49: Justin Ross | D49: Justin | E49: Ross | F49: =IF(Names!$B49="M","Mr.",IF(Names!$B49="F","Ms.","Mx.")) -> Mr. | G49: =IF(Names!$B49="M","he",IF(Names!$B49="F","she","they")) -> he | H49: =IF(Names!$B49="M","him",IF(Names!$B49="F","her","them")) -> him | I49: =IF(Names!$B49="M","his",IF(Names!$B49="F","her","their")) -> his
A50: 49 | B50: M | C50: =D50&" "&E50 -> Adam Hart | D50: Adam | E50: Hart | F50: =IF(Names!$B50="M","Mr.",IF(Names!$B50="F","Ms.","Mx.")) -> Mr. | G50: =IF(Names!$B50="M","he",IF(Names!$B50="F","she","they")) -> he | H50: =IF(Names!$B50="M","him",IF(Names!$B50="F","her","them")) -> him | I50: =IF(Names!$B50="M","his",IF(Names!$B50="F","her","their")) -> his
A51: 50 | B51: M | C51: =D51&" "&E51 -> Aidan Lewis | D51: Aidan | E51: Lewis | F51: =IF(Names!$B51="M","Mr.",IF(Names!$B51="F","Ms.","Mx.")) -> Mr. | G51: =IF(Names!$B51="M","he",IF(Names!$B51="F","she","they")) -> he | H51: =IF(Names!$B51="M","him",IF(Names!$B51="F","her","them")) -> him | I51: =IF(Names!$B51="M","his",IF(Names!$B51="F","her","their")) -> his
A52: 51 | B52: M | C52: =D52&" "&E52 -> Isaac Rose | D52: Isaac | E52: Rose | F52: =IF(Names!$B52="M","Mr.",IF(Names!$B52="F","Ms.","Mx.")) -> Mr. | G52: =IF(Names!$B52="M","he",IF(Names!$B52="F","she","they")) -> he | H52: =IF(Names!$B52="M","him",IF(Names!$B52="F","her","them")) -> him | I52: =IF(Names!$B52="M","his",IF(Names!$B52="F","her","their")) -> his
A53: 52 | B53: M | C53: =D53&" "&E53 -> Jackson Allen | D53: Jackson | E53: Allen | F53: =IF(Names!$B53="M","Mr.",IF(Names!$B53="F","Ms.","Mx.")) -> Mr. | G53: =IF(Names!$B53="M","he",IF(Names!$B53="F","she","they")) -> he | H53: =IF(Names!$B53="M","him",IF(Names!$B53="F","her","them")) -> him | I53: =IF(Names!$B53="M","his",IF(Names!$B53="F","her","their")) -> his
A54: 53 | B54: M | C54: =D54&" "&E54 -> Oliver Simpson | D54: Oliver | E54: Simpson | F54: =IF(Names!$B54="M","Mr.",IF(Names!$B54="F","Ms.","Mx.")) -> Mr. | G54: =IF(Names!$B54="M","he",IF(Names!$B54="F","she","they")) -> he | H54: =IF(Names!$B54="M","him",IF(Names!$B54="F","her","them")) -> him | I54: =IF(Names!$B54="M","his",IF(Names!$B54="F","her","their")) -> his
A55: 54 | B55: M | C55: =D55&" "&E55 -> Brycen Ingram | D55: Brycen | E55: Ingram | F55: =IF(Names!$B55="M","Mr.",IF(Names!$B55="F","Ms.","Mx.")) -> Mr. | G55: =IF(Names!$B55="M","he",IF(Names!$B55="F","she","they")) -> he | H55: =IF(Names!$B55="M","him",IF(Names!$B55="F","her","them")) -> him | I55: =IF(Names!$B55="M","his",IF(Names!$B55="F","her","their")) -> his
A56: 55 | B56: M | C56: =D56&" "&E56 -> Ibrahim Berg | D56: Ibrahim | E56: Berg | F56: =IF(Names!$B56="M","Mr.",IF(Names!$B56="F","Ms.","Mx.")) -> Mr. | G56: =IF(Names!$B56="M","he",IF(Names!$B56="F","she","they")) -> he | H56: =IF(Names!$B56="M","him",IF(Names!$B56="F","her","them")) -> him | I56: =IF(Names!$B56="M","his",IF(Names!$B56="F","her","their")) -> his
A57: 56 | B57: M | C57: =D57&" "&E57 -> Uriel Kirk | D57: Uriel | E57: Kirk | F57: =IF(Names!$B57="M","Mr.",IF(Names!$B57="F","Ms.","Mx.")) -> Mr. | G57: =IF(Names!$B57="M","he",IF(Names!$B57="F","she","they")) -> he | H57: =IF(Names!$B57="M","him",IF(Names!$B57="F","her","them")) -> him | I57: =IF(Names!$B57="M","his",IF(Names!$B57="F","her","their")) -> his
A58: 57 | B58: M | C58: =D58&" "&E58 -> Bronson Marsh | D58: Bronson | E58: Marsh | F58: =IF(Names!$B58="M","Mr.",IF(Names!$B58="F","Ms.","Mx.")) -> Mr. | G58: =IF(Names!$B58="M","he",IF(Names!$B58="F","she","they")) -> he | H58: =IF(Names!$B58="M","him",IF(Names!$B58="F","her","them")) -> him | I58: =IF(Names!$B58="M","his",IF(Names!$B58="F","her","their")) -> his
A59: 58 | B59: M | C59: =D59&" "&E59 -> Juelz Gibbs | D59: Juelz | E59: Gibbs | F59: =IF(Names!$B59="M","Mr.",IF(Names!$B59="F","Ms.","Mx.")) -> Mr. | G59: =IF(Names!$B59="M","he",IF(Names!$B59="F","she","they")) -> he | H59: =IF(Names!$B59="M","him",IF(Names!$B59="F","her","them")) -> him | I59: =IF(Names!$B59="M","his",IF(Names!$B59="F","her","their")) -> his
A60: 59 | B60: M | C60: =D60&" "&E60 -> Bobby Harvey | D60: Bobby | E60: Harvey | F60: =IF(Names!$B60="M","Mr.",IF(Names!$B60="F","Ms.","Mx.")) -> Mr. | G60: =IF(Names!$B60="M","he",IF(Names!$B60="F","she","they")) -> he | H60: =IF(Names!$B60="M","him",IF(Names!$B60="F","her","them")) -> him | I60: =IF(Names!$B60="M","his",IF(Names!$B60="F","her","their")) -> his
A61: 60 | B61: M | C61: =D61&" "&E61 -> Henry Matthews | D61: Henry | E61: Matthews | F61: =IF(Names!$B61="M","Mr.",IF(Names!$B61="F","Ms.","Mx.")) -> Mr. | G61: =IF(Names!$B61="M","he",IF(Names!$B61="F","she","they")) -> he | H61: =IF(Names!$B61="M","him",IF(Names!$B61="F","her","them")) -> him | I61: =IF(Names!$B61="M","his",IF(Names!$B61="F","her","their")) -> his
... A169: 168 | B169: M | C169: =D169&" "&E169 -> Fawwaaz al-Zaman | D169: Fawwaaz | E169: al-Zaman | F169: =IF(Names!$B169="M","Mr.",IF(Names!$B169="F","Ms.","Mx.")) -> Mr. | G169: =IF(Names!$B169="M","he",IF(Names!$B169="F","she","they")) -> he | H169: =IF(Names!$B169="M","him",IF(Names!$B169="F","her","them")) -> him | I169: =IF(Names!$B169="M","his",IF(Names!$B169="F","her","their")) -> his
A170: 169 | B170: M | C170: Alon Liebermann | D170: Alon | E170: Liebermann | F170: =IF(Names!$B170="M","Mr.",IF(Names!$B170="F","Ms.","Mx.")) -> Mr. | G170: =IF(Names!$B170="M","he",IF(Names!$B170="F","she","they")) -> he | H170: =IF(Names!$B170="M","him",IF(Names!$B170="F","her","them")) -> him | I170: =IF(Names!$B170="M","his",IF(Names!$B170="F","her","their")) -> his
A171: 170 | B171: M | C171: Jamian Montefiore | D171: Jamian | E171: Montefiore | F171: =IF(Names!$B171="M","Mr.",IF(Names!$B171="F","Ms.","Mx.")) -> Mr. | G171: =IF(Names!$B171="M","he",IF(Names!$B171="F","she","they")) -> he | H171: =IF(Names!$B171="M","him",IF(Names!$B171="F","her","them")) -> him | I171: =IF(Names!$B171="M","his",IF(Names!$B171="F","her","their")) -> his
A172: 171 | B172: M | C172: Che Rubin | D172: Che | E172: Rubin | F172: =IF(Names!$B172="M","Mr.",IF(Names!$B172="F","Ms.","Mx.")) -> Mr. | G172: =IF(Names!$B172="M","he",IF(Names!$B172="F","she","they")) -> he | H172: =IF(Names!$B172="M","him",IF(Names!$B172="F","her","them")) -> him | I172: =IF(Names!$B172="M","his",IF(Names!$B172="F","her","their")) -> his
A173: 172 | B173: M | C173: Judah Schalit | D173: Judah | E173: Schalit | F173: =IF(Names!$B173="M","Mr.",IF(Names!$B173="F","Ms.","Mx.")) -> Mr. | G173: =IF(Names!$B173="M","he",IF(Names!$B173="F","she","they")) -> he | H173: =IF(Names!$B173="M","him",IF(Names!$B173="F","her","them")) -> him | I173: =IF(Names!$B173="M","his",IF(Names!$B173="F","her","their")) -> his
A174: 173 | B174: M | C174: Paz Levin | D174: Paz | E174: Levin | F174: =IF(Names!$B174="M","Mr.",IF(Names!$B174="F","Ms.","Mx.")) -> Mr. | G174: =IF(Names!$B174="M","he",IF(Names!$B174="F","she","they")) -> he | H174: =IF(Names!$B174="M","him",IF(Names!$B174="F","her","them")) -> him | I174: =IF(Names!$B174="M","his",IF(Names!$B174="F","her","their")) -> his
A175: 174 | B175: M | C175: Avidan Wakstok | D175: Avidan | E175: Wakstok | F175: =IF(Names!$B175="M","Mr.",IF(Names!$B175="F","Ms.","Mx.")) -> Mr. | G175: =IF(Names!$B175="M","he",IF(Names!$B175="F","she","they")) -> he | H175: =IF(Names!$B175="M","him",IF(Names!$B175="F","her","them")) -> him | I175: =IF(Names!$B175="M","his",IF(Names!$B175="F","her","their")) -> his
A176: 175 | B176: M | C176: Pessach Liss | D176: Pessach | E176: Liss | F176: =IF(Names!$B176="M","Mr.",IF(Names!$B176="F","Ms.","Mx.")) -> Mr. | G176: =IF(Names!$B176="M","he",IF(Names!$B176="F","she","they")) -> he | H176: =IF(Names!$B176="M","him",IF(Names!$B176="F","her","them")) -> him | I176: =IF(Names!$B176="M","his",IF(Names!$B176="F","her","their")) -> his
A177: 176 | B177: M | C177: Yehuda Horowitz | D177: Yehuda | E177: Horowitz | F177: =IF(Names!$B177="M","Mr.",IF(Names!$B177="F","Ms.","Mx.")) -> Mr. | G177: =IF(Names!$B177="M","he",IF(Names!$B177="F","she","they")) -> he | H177: =IF(Names!$B177="M","him",IF(Names!$B177="F","her","them")) -> him | I177: =IF(Names!$B177="M","his",IF(Names!$B177="F","her","their")) -> his
A178: 177 | B178: M | C178: Zimra Mazar | D178: Zimra | E178: Mazar | F178: =IF(Names!$B178="M","Mr.",IF(Names!$B178="F","Ms.","Mx.")) -> Mr. | G178: =IF(Names!$B178="M","he",IF(Names!$B178="F","she","they")) -> he | H178: =IF(Names!$B178="M","him",IF(Names!$B178="F","her","them")) -> him | I178: =IF(Names!$B178="M","his",IF(Names!$B178="F","her","their")) -> his
A179: 178 | B179: M | C179: Lavan Frankau | D179: Lavan | E179: Frankau | F179: =IF(Names!$B179="M","Mr.",IF(Names!$B179="F","Ms.","Mx.")) -> Mr. | G179: =IF(Names!$B179="M","he",IF(Names!$B179="F","she","they")) -> he | H179: =IF(Names!$B179="M","him",IF(Names!$B179="F","her","them")) -> him | I179: =IF(Names!$B179="M","his",IF(Names!$B179="F","her","their")) -> his
A180: 179 | B180: M | C180: Amasa Kalish | D180: Amasa | E180: Kalish | F180: =IF(Names!$B180="M","Mr.",IF(Names!$B180="F","Ms.","Mx.")) -> Mr. | G180: =IF(Names!$B180="M","he",IF(Names!$B180="F","she","they")) -> he | H180: =IF(Names!$B180="M","him",IF(Names!$B180="F","her","them")) -> him | I180: =IF(Names!$B180="M","his",IF(Names!$B180="F","her","their")) -> his
A181: 180 | B181: M | C181: Oris Aidallbery | D181: Oris | E181: Aidallbery | F181: =IF(Names!$B181="M","Mr.",IF(Names!$B181="F","Ms.","Mx.")) -> Mr. | G181: =IF(Names!$B181="M","he",IF(Names!$B181="F","she","they")) -> he | H181: =IF(Names!$B181="M","him",IF(Names!$B181="F","her","them")) -> him | I181: =IF(Names!$B181="M","his",IF(Names!$B181="F","her","their")) -> his
... A254: 253 | B254: F | C254: Annie Thomson | D254: Annie | E254: Thomson | F254: =IF(Names!$B254="M","Mr.",IF(Names!$B254="F","Ms.","Mx.")) -> Ms. | G254: =IF(Names!$B254="M","he",IF(Names!$B254="F","she","they")) -> she | H254: =IF(Names!$B254="M","him",IF(Names!$B254="F","her","them")) -> her | I254: =IF(Names!$B254="M","his",IF(Names!$B254="F","her","their")) -> her
...

Sheet AssetServiceCosts
A1: Code | B1: Item | C1: Low | D1: High | E1: FLow | F1: FHigh | G1: Column1 | H1: ASSET/SERVICE
A2: 1 | B2: Student loan | C2: 5000 | D2: 30000 | E2: 50 | F2: 300 | G2: =RANDBETWEEN(50,300)*100 -> 25500 | H2: SERVICE
A3: 2 | B3: Business loan | C3: 10000 | D3: 150000 | E3: 100 | F3: 1500 | G3: =RANDBETWEEN(100,1500)*100 -> 116400 | H3: SERVICE
A4: 3 | B4: Home renovation | C4: 20000 | D4: 100000 | E4: 200 | F4: 1000 | G4: =RANDBETWEEN(200,1000)*100 -> 35700
A5: 4 | B5: Debt consolidation | C5: 5000 | D5: 17000 | E5: 50 | F5: 170 | G5: =RANDBETWEEN(50,170)*100 -> 16700 | H5: SERVICE
A6: 5 | B6: Medical expense | C6: 5000 | D6: 22000 | E6: 50 | F6: 220 | G6: =RANDBETWEEN(50,220)*100 -> 11700 | H6: SERVICE
A7: 6 | B7: Wedding | C7: 3000 | D7: 8000 | E7: 30 | F7: 80 | G7: =RANDBETWEEN(30,80)*100 -> 7600 | H7: SERVICE
A8: 7 | B8: Vacation | C8: 2000 | D8: 7000 | E8: 20 | F8: 70 | G8: =RANDBETWEEN(20,70)*100 -> 6600 | H8: SERVICE
A9: 8 | B9: New kitchen appliance | C9: 1000 | D9: 4000 | E9: 10 | F9: 40 | G9: =RANDBETWEEN(10,40)*100 -> 4000 | H9: ASSET
A10: 9 | B10: Camper | C10: 10000 | D10: 20000 | E10: 100 | F10: 200 | G10: =RANDBETWEEN(100,200)*100 -> 14500 | H10: ASSET
A11: 10 | B11: Pet's surgery | C11: 1000 | D11: 3000 | E11: 10 | F11: 30 | G11: =RANDBETWEEN(10,30)*100 -> 1600 | H11: SERVICE
A12: 11 | B12: Computer | C12: 800 | D12: 2500 | E12: 8 | F12: 25 | G12: =RANDBETWEEN(8,25)*100 -> 800 | H12: ASSET
A13: 12 | B13: Smart phone | C13: 800 | D13: 2000 | E13: 8 | F13: 20 | G13: =RANDBETWEEN(8,20)*100 -> 900 | H13: ASSET
A14: 13 | B14: Professional certification | C14: 1200 | D14: 3600 | E14: 12 | F14: 36 | G14: =RANDBETWEEN(12,36)*100 -> 1900 | H14: SERVICE
A15: 14 | B15: Home security upgrade | C15: 1000 | D15: 6000 | E15: 10 | F15: 60 | G15: =RANDBETWEEN(10,60)*100 -> 5900 | H15: ASSET
A16: 15 | B16: Hot water heater | C16: 800 | D16: 2200 | E16: 8 | F16: 22 | G16: =RANDBETWEEN(8,22)*100 -> 2200 | H16: ASSET
A17: 16 | B17: Stereo system | C17: 1500 | D17: 3000 | E17: 15 | F17: 30 | G17: =RANDBETWEEN(15,30)*100 -> 2100 | H17: ASSET
A18: 17 | B18: Roof repair | C18: 10000 | D18: 25000 | E18: 100 | F18: 250 | G18: =RANDBETWEEN(100,250)*100 -> 15800 | H18: SERVICE
A19: 18 | B19: Jetski | C19: 12000 | D19: 18000 | E19: 120 | F19: 180 | G19: =RANDBETWEEN(120,180)*100 -> 16600 | H19: ASSET
A20: 19 | B20: Electrical redundancy system | C20: 10000 | D20: 80000 | E20: 100 | F20: 800 | G20: =RANDBETWEEN(100,800)*100 -> 39000 | H20: ASSET
A21: 20 | B21: Emergency dental visit | C21: 500 | D21: 5000 | E21: 5 | F21: 50 | G21: =RANDBETWEEN(5,50)*100 -> 600 | H21: SERVICE
A22: 21 | B22: Childcare program | C22: 1000 | D22: 7000 | E22: 10 | F22: 70 | G22: =RANDBETWEEN(10,70)*100 -> 2700 | H22: SERVICE
A23: 22 | B23: Funeral | C23: 3000 | D23: 15000 | E23: 30 | F23: 150 | G23: =RANDBETWEEN(30,150)*100 -> 13200 | H23: SERVICE
A24: 23 | B24: Home insulation upgrade | C24: 2000 | D24: 10000 | E24: 20 | F24: 100 | G24: =RANDBETWEEN(20,100)*100 -> 5000
A25: 24 | B25: Vehicle repair | C25: 800 | D25: 5000 | E25: 8 | F25: 50 | G25: =RANDBETWEEN(8,50)*100 -> 1000 | H25: SERVICE
A26: 25 | B26: Solar panel installation | C26: 8000 | D26: 25000 | E26: 80 | F26: 250 | G26: =RANDBETWEEN(80,250)*100 -> 20500 | H26: ASSET
A27: 26 | B27: Mobility aid (e.g., wheelchair, lift) | C27: 2000 | D27: 12000 | E27: 20 | F27: 120 | G27: =RANDBETWEEN(20,120)*100 -> 11700 | H27: ASSET
A28: 27 | B28: Small business startup | C28: 5000 | D28: 50000 | E28: 50 | F28: 500 | G28: =RANDBETWEEN(50,500)*100 -> 20700 | H28: SERVICE
A29: 28 | B29: Business registration fee | C29: 2000 | D29: 12000 | E29: 20 | F29: 120 | G29: =RANDBETWEEN(20,120)*100 -> 2700 | H29: SERVICE
A30: 29 | B30: Household furniture set | C30: 1000 | D30: 7000 | E30: 10 | F30: 70 | G30: =RANDBETWEEN(10,70)*100 -> 4000 | H30: ASSET
A31: 30 | B31: Home office setup | C31: 1500 | D31: 6000 | E31: 15 | F31: 60 | G31: =RANDBETWEEN(15,60)*100 -> 3900 | H31: ASSET
A32: 31 | B32: Solar home heating system | C32: 3000 | D32: 20000 | E32: 30 | F32: 200 | G32: =RANDBETWEEN(30,200)*100 -> 19000 | H32: ASSET
A33: 32 | B33: Hybrid vehicle down payment | C33: 10000 | D33: 40000 | E33: 100 | F33: 400 | G33: =RANDBETWEEN(100,400)*100 -> 20300 | H33: ASSET
A34: 33 | B34: Replacement refrigerator | C34: 1200 | D34: 3500 | E34: 12 | F34: 35 | G34: =RANDBETWEEN(12,35)*100 -> 2400 | H34: ASSET
A35: 34 | B35: Plumbing repair tool | C35: 2000 | D35: 10000 | E35: 20 | F35: 100 | G35: =RANDBETWEEN(20,100)*100 -> 3800 | H35: ASSET
A36: 35 | B36: Dental alignment appliance | C36: 3000 | D36: 8000 | E36: 30 | F36: 80 | G36: =RANDBETWEEN(30,80)*100 -> 7600 | H36: SERVICE
A37: 36 | B37: Cultural celebration (e.g., wedding, quinceañera) | C37: 5000 | D37: 20000 | E37: 50 | F37: 200 | G37: =RANDBETWEEN(50,200)*100 -> 5600 | H37: SERVICE
A38: 37 | B38: Home theater projector | C38: 2000 | D38: 10000 | E38: 20 | F38: 100 | G38: =RANDBETWEEN(20,100)*100 -> 6400 | H38: ASSET
A39: 38 | B39: Surround sound system | C39: 2000 | D39: 10000 | E39: 20 | F39: 100 | G39: =RANDBETWEEN(20,100)*100 -> 6700 | H39: ASSET
A40: 39 | B40: Family holiday | C40: 1000 | D40: 7000 | E40: 10 | F40: 70 | G40: =RANDBETWEEN(10,70)*100 -> 3900 | H40: SERVICE
...

Sheet ObjectUserCosts
A1: Code | B1: Object | C1: QtyinPack | D1: UnitLow | E1: UnitHigh | F1: PersonUses | G1: Category | H1: UnitSINGULAR | I1: UnitPLURAL | J1: ProfessionArticle | K1: ObjectSingular
A2: 86 | B2: hand-held calculators | C2: 1 | D2: 5 | E2: 15 | F2: accountant | G2: Discrete Asset | H2: calculator | I2: calculators | J2: an | K2: calculators
A3: 74 | B3: rolls of electrical tape | C3: 1 | D3: 1.5 | E3: 4 | F3: appliance repairer | G3: Ambiguous | H3: roll | I3: rolls | J3: an | K3: tape
A4: 53 | B4: small hand trowels | C4: 1 | D4: 3 | E4: 7 | F4: archaeologist | G4: Discrete Asset | H4: trowel | I4: trowels | J4: an | K4: trowels
A5: 47 | B5: filing folders | C5: 100 | D5: 8 | E5: 20 | F5: archivist | G5: Discrete Asset | H5: folder | I5: folders | J5: an | K5: folders
A6: 7 | B6: small paintbrushes | C6: 1 | D6: 0.85 | E6: 3.5 | F6: artist | G6: Discrete Asset | H6: paintbrush | I6: paintbrushes | J6: an | K6: paintbrushes
A7: 31 | B7: sets of allen wrenches | C7: 1 | D7: 5 | E7: 20 | F7: assembler | G7: Discrete Asset | H7: set | I7: sets | J7: an | K7: wrenches
A8: 26 | B8: loaves of sourdough bread | C8: 1 | D8: 4.5 | E8: 8 | F8: baker | G8: Measurable/Consumable | H8: loaf | I8: loaves | J8: a | K8: bread
A9: 36 | B9: cans of shaving cream | C9: 1 | D9: 2.5 | E9: 6.5 | F9: barber | G9: Measurable/Consumable | H9: can | I9: cans | J9: a | K9: shaving cream
A10: 12 | B10: pounds of coffee beans | C10: 1 | D10: 8.5 | E10: 16 | F10: barista | G10: Measurable/Consumable | H10: pound | I10: pounds | J10: a | K10: coffee beans
A11: 13 | B11: kilograms of coffee beans | C11: 1 | D11: 18 | E11: 31 | F11: barista | G11: Measurable/Consumable | H11: kilogram | I11: kilograms | J11: a | K11: coffee beans
A12: 69 | B12: small cans of wd-40 | C12: 1 | D12: 4 | E12: 9 | F12: bicycle repairperson | G12: Measurable/Consumable | H12: can | I12: cans | J12: a | K12: wd-40
A13: 5 | B13: 8 foot pine 2x4 planks | C13: 1 | D13: 9.54 | E13: 19.09 | F13: builder | G13: Discrete Asset | H13: plank | I13: planks | J13: a | K13: planks
... A104: 49 | B104: canisters of propane | C104: 1 | D104: 4 | E104: 7 | F104: welder | G104: Ambiguous | H104: canister | I104: canisters | J104: a | K104: propane

Sheet RateScenarios
A1: verb | B1: obj1 | C1: obj2 | D1: obj3 | E1: total_phrase
A2: sold | B2: cupcakes | C2: books | D2: tickets | E2: earned a total of | H2: use: [name] [verb] [random value] [select one of the three objects] and [total_phrase]
A3: earned | B3: money | C3: rewards | D3: points | E3: earned a total of | H3: choose(randbetween(1,3),obj1,obj2,obj3)
A4: drove | B4: miles | C4: kilometers | D4: laps | E4: traveled a total of
A5: built | B5: shelves | C5: houses | D5: models | E5: constructed a total of
A6: created | B6: videos | C6: artworks | D6: songs | E6: created a total of
A7: planted | B7: trees | C7: flowers | D7: vegetables | E7: planted a total of
A8: completed | B8: assignments | C8: projects | D8: courses | E8: completed a total of
A9: cooked | B9: meals | C9: dishes | D9: cakes | E9: prepared a total of
A10: gave | B10: gifts | C10: donations | D10: lessons | E10: gave a total of
A11: explored | B11: caves | C11: trails | D11: cities | E11: explored a total of
A12: fed | B12: animals | C12: birds | D12: guests | E12: fed a total of
A13: made | B13: crafts | C13: mistakes | D13: calls | E13: made a total of
A14: took | B14: photos | C14: samples | D14: notes | E14: took a total of
A15: saw | B15: movies | C15: animals | D15: stars | E15: saw a total of
... A51: sketched | B51: portraits | C51: designs | D51: buildings | E51: sketched a total of

Sheet Municipalities
A1: Code | B1: MunName | C1: Property_Address | D1: MunCode | E1: Dwelling_Units | F1: Frontage(ft) | G1: Total_Value
A2: 1 | B2: R.M. of Redwood Creek | C2: 306 VALHOP DR | D2: 143 | E2: 1 | F2: 80 | G2: 786200
A3: 2 | B3: City of Twin Harbors | C3: 118 BRANDT ST | D3: 152 | E3: 1 | F3: 111.53 | G3: 736300
A4: 3 | B4: Ironwood Bay City | C4: 241 #5 HWY E | D4: 182 | E4: 1 | F4: 250 | G4: 699800
A5: 4 | B5: R.M. of Redwood Creek | C5: 30 LAKEVIEW DR | D5: 143 | E5: 1 | F5: 100 | G5: 669000
A6: 5 | B6: City of Twin Harbors | C6: 66 WATERS EDGE DR | D6: 152 | E6: 1 | F6: 100 | G6: 641200
A7: 6 | B7: City of Twin Harbors | C7: 76 BRANDT ST | D7: 152 | E7: 1 | F7: 120 | G7: 628800
A8: 7 | B8: Ironwood Bay City | C8: 16 LAKEVIEW LANE | D8: 182 | E8: 1 | F8: 125 | G8: 599900
A9: 8 | B9: Ironwood Bay City | C9: 8 LAKEVIEW LANE | D9: 182 | E9: 1 | F9: 100 | G9: 552600
A10: 9 | B10: City of Twin Harbors | C10: DESC 1--60216 | D10: 152 | E10: 1 | F10: 120 | G10: 545000
A11: 10 | B11: Ironwood Bay City | C11: 2 LAKEVIEW LANE | D11: 182 | E11: 1 | F11: 100 | G11: 530400
A12: 11 | B12: Triton Valley Municipality | C12: 242 LAKE AVE | D12: 333 | E12: 1 | F12: 80 | G12: 527900
A13: 12 | B13: Ironwood Bay City | C13: 51 ONOFRIECHUK DR | D13: 182 | E13: 1 | F13: 120 | G13: 490000
... A3791: 3790 | B3791: Ironwood Bay City | C3791: 141 5TH AVE SW | D3791: 182 | E3791: 1 | F3791: 50 | G3791: 100100

Sheet Vehicles
A1: Code | B1: Make | C1: Model | D1: Package | E1: FullName | K1: Code | L1: RepairItem | M1: CostLOW | N1: CostHIGH | O1: TimeLOW | P1: TimeHIGH | Q1: QTY
A2: 1 | B2: Subvoof | C2: Oracle | D2: =CHAR(RANDBETWEEN(65,90))&CHAR(RANDBETWEEN(65,90))&CHAR(RANDBETWEEN(48,57)) -> OV9 | E2: =PROPER(B2)&" "&PROPER(C2)&" "&D2 -> Subvoof Oracle OV9 | K2: 1 | L2: Oil Change | M2: 90 | N2: 150 | O2: 0.05 | P2: 0.05 | Q2: 1 | S2: Spill across columns:
A3: 2 | B3: Unxop | C3: Aura | D3: =CHAR(RANDBETWEEN(65,90))&CHAR(RANDBETWEEN(65,90))&CHAR(RANDBETWEEN(48,57)) -> CB2 | E3: =PROPER(B3)&" "&PROPER(C3)&" "&D3 -> Unxop Aura CB2 | K3: 2 | L3: Tire Rotation | M3: 40 | N3: 80 | O3: 0.05 | P3: 0.05 | Q3: 1 | S3: Code | T3: Item | U3: Cost | V3: Time
A4: 3 | B4: xiw | C4: Capital | D4: =CHAR(RANDBETWEEN(65,90))&CHAR(RANDBETWEEN(65,90))&CHAR(RANDBETWEEN(48,57)) -> FB1 | E4: =PROPER(B4)&" "&PROPER(C4)&" "&D4 -> Xiw Capital FB1 | K4: 3 | L4: Wheel Alignment | M4: 120 | N4: 200 | O4: 1 | P4: 1.5 | Q4: 1
A5: 4 | B5: thruma | C5: Sliver | D5: =CHAR(RANDBETWEEN(65,90))&CHAR(RANDBETWEEN(65,90))&CHAR(RANDBETWEEN(48,57)) -> HQ7 | E5: =PROPER(B5)&" "&PROPER(C5)&" "&D5 -> Thruma Sliver HQ7 | K5: 4 | L5: Engine Air Filter Replacement | M5: 60 | N5: 120 | O5: 0.2 | P5: 0.5 | Q5: 1
A6: 5 | B6: stifoom | C6: Inception | D6: =CHAR(RANDBETWEEN(65,90))&CHAR(RANDBETWEEN(65,90))&CHAR(RANDBETWEEN(48,57)) -> KJ6 | E6: =PROPER(B6)&" "&PROPER(C6)&" "&D6 -> Stifoom Inception KJ6 | K6: 5 | L6: Cabin Air Filter Replacement | M6: 70 | N6: 150 | O6: 0.3 | P6: 0.8 | Q6: 1
A7: 6 | B7: clirted | C7: Trailblazer | D7: =CHAR(RANDBETWEEN(65,90))&CHAR(RANDBETWEEN(65,90))&CHAR(RANDBETWEEN(48,57)) -> BL9 | E7: =PROPER(B7)&" "&PROPER(C7)&" "&D7 -> Clirted Trailblazer BL9 | K7: 6 | L7: Wiper Blade Replacement (Pair) | M7: 50 | N7: 100 | O7: 0.2 | P7: 0.2 | Q7: 2
A8: 7 | B8: Init | C8: Blend | D8: =CHAR(RANDBETWEEN(65,90))&CHAR(RANDBETWEEN(65,90))&CHAR(RANDBETWEEN(48,57)) -> JS5 | E8: =PROPER(B8)&" "&PROPER(C8)&" "&D8 -> Init Blend JS5 | K8: 7 | L8: Brake Fluid Flush | M8: 100 | N8: 180 | O8: 0.8 | P8: 1.2 | Q8: 1
A9: 8 | B9: Outoat | C9: Presence | D9: =CHAR(RANDBETWEEN(65,90))&CHAR(RANDBETWEEN(65,90))&CHAR(RANDBETWEEN(48,57)) -> SW9 | E9: =PROPER(B9)&" "&PROPER(C9)&" "&D9 -> Outoat Presence SW9 | K9: 8 | L9: Coolant (Antifreeze) Flush | M9: 150 | N9: 250 | O9: 1 | P9: 1.5 | Q9: 1
A10: 9 | B10: Intervop | C10: Thunder | D10: =CHAR(RANDBETWEEN(65,90))&CHAR(RANDBETWEEN(65,90))&CHAR(RANDBETWEEN(48,57)) -> VC3 | E10: =PROPER(B10)&" "&PROPER(C10)&" "&D10 -> Intervop Thunder VC3 | K10: 9 | L10: Transmission Fluid Change | M10: 200 | N10: 400 | O10: 1 | P10: 2 | Q10: 1
A11: 10 | B11: iapu | C11: Astral | D11: =CHAR(RANDBETWEEN(65,90))&CHAR(RANDBETWEEN(65,90))&CHAR(RANDBETWEEN(48,57)) -> XY1 | E11: =PROPER(B11)&" "&PROPER(C11)&" "&D11 -> Iapu Astral XY1 | K11: 10 | L11: Power Steering Fluid Flush | M11: 100 | N11: 200 | O11: 0.8 | P11: 1.2 | Q11: 1
A12: 11 | B12: Posttist | C12: Spire | D12: =CHAR(RANDBETWEEN(65,90))&CHAR(RANDBETWEEN(65,90))&CHAR(RANDBETWEEN(48,57)) -> VM4 | E12: =PROPER(B12)&" "&PROPER(C12)&" "&D12 -> Posttist Spire VM4 | K12: 11 | L12: New Tires (Set of 4, All-Season) | M12: 600 | N12: 1200 | O12: 1 | P12: 1.5 | Q12: 2 or 4
A13: 12 | B13: Antibest | C13: Fang | D13: =CHAR(RANDBETWEEN(65,90))&CHAR(RANDBETWEEN(65,90))&CHAR(RANDBETWEEN(48,57)) -> DL1 | E13: =PROPER(B13)&" "&PROPER(C13)&" "&D13 -> Antibest Fang DL1 | K13: 12 | L13: Tire Mount & Balance (Set of 4) | M13: 100 | N13: 160 | O13: 1 | P13: 1.5 | Q13: 2 or 4
A14: 13 | B14: wucko | C14: Fragment | D14: =CHAR(RANDBETWEEN(65,90))&CHAR(RANDBETWEEN(65,90))&CHAR(RANDBETWEEN(48,57)) -> UZ1 | E14: =PROPER(B14)&" "&PROPER(C14)&" "&D14 -> Wucko Fragment UZ1 | K14: 13 | L14: Tire Repair (Plug) | M14: 30 | N14: 60 | O14: 0.3 | P14: 0.3 | Q14: 1
A15: 14 | B15: prup | C15: Freedom | D15: =CHAR(RANDBETWEEN(65,90))&CHAR(RANDBETWEEN(65,90))&CHAR(RANDBETWEEN(48,57)) -> RQ8 | E15: =PROPER(B15)&" "&PROPER(C15)&" "&D15 -> Prup Freedom RQ8 | K15: 14 | L15: Brake Pad Replacement | M15: 250 | N15: 450 | O15: 1 | P15: 1.8 | Q15: 4
A16: 15 | B16: kuwife | C16: Mythic | D16: =CHAR(RANDBETWEEN(65,90))&CHAR(RANDBETWEEN(65,90))&CHAR(RANDBETWEEN(48,57)) -> XH1 | E16: =PROPER(B16)&" "&PROPER(C16)&" "&D16 -> Kuwife Mythic XH1 | K16: 15 | L16: Brake Rotors | M16: 250 | N16: 450 | O16: 1.5 | P16: 2.5 | Q16: 4
A17: 16 | B17: mileel | C17: Dusk | D17: =CHAR(RANDBETWEEN(65,90))&CHAR(RANDBETWEEN(65,90))&CHAR(RANDBETWEEN(48,57)) -> CZ5 | E17: =PROPER(B17)&" "&PROPER(C17)&" "&D17 -> Mileel Dusk CZ5 | K17: 16 | L17: Brake Caliper Replacement (Pair) | M17: 600 | N17: 900 | O17: 1 | P17: 1.5 | Q17: 4
A18: 17 | B18: Proat | C18: Mystery | D18: =CHAR(RANDBETWEEN(65,90))&CHAR(RANDBETWEEN(65,90))&CHAR(RANDBETWEEN(48,57)) -> EG5 | E18: =PROPER(B18)&" "&PROPER(C18)&" "&D18 -> Proat Mystery EG5 | K18: 17 | L18: Battery Replacement | M18: 200 | N18: 350 | O18: 0.3 | P18: 1 | Q18: 1
A19: 18 | B19: Inake | C19: Tigress | D19: =CHAR(RANDBETWEEN(65,90))&CHAR(RANDBETWEEN(65,90))&CHAR(RANDBETWEEN(48,57)) -> RE1 | E19: =PROPER(B19)&" "&PROPER(C19)&" "&D19 -> Inake Tigress RE1 | K19: 18 | L19: Spark Plug Replacement (full set) | M19: 150 | N19: 300 | O19: 1 | P19: 1.5 | Q19: 4 or 6
A20: 19 | B20: Contragon | C20: Vision | D20: =CHAR(RANDBETWEEN(65,90))&CHAR(RANDBETWEEN(65,90))&CHAR(RANDBETWEEN(48,57)) -> NE5 | E20: =PROPER(B20)&" "&PROPER(C20)&" "&D20 -> Contragon Vision NE5 | K20: 19 | L20: Serpentine Belt Replacement | M20: 150 | N20: 300 | O20: 0.8 | P20: 1.5 | Q20: 1
A21: 20 | B21: aqa | C21: Excursion | D21: =CHAR(RANDBETWEEN(65,90))&CHAR(RANDBETWEEN(65,90))&CHAR(RANDBETWEEN(48,57)) -> MR1 | E21: =PROPER(B21)&" "&PROPER(C21)&" "&D21 -> Aqa Excursion MR1 | K21: 20 | L21: Timing Belt Replacement | M21: 800 | N21: 1500 | O21: 4 | P21: 8 | Q21: 1
A22: 21 | B22: Autocife | C22: Prodigy | D22: =CHAR(RANDBETWEEN(65,90))&CHAR(RANDBETWEEN(65,90))&CHAR(RANDBETWEEN(48,57)) -> AN8 | E22: =PROPER(B22)&" "&PROPER(C22)&" "&D22 -> Autocife Prodigy AN8 | K22: 21 | L22: Ignition Coil Replacement (One) | M22: 150 | N22: 300 | O22: 0.3 | P22: 1 | Q22: 1
A23: 22 | B23: Nonxine | C23: Vulture | D23: =CHAR(RANDBETWEEN(65,90))&CHAR(RANDBETWEEN(65,90))&CHAR(RANDBETWEEN(48,57)) -> MY8 | E23: =PROPER(B23)&" "&PROPER(C23)&" "&D23 -> Nonxine Vulture MY8 | K23: 22 | L23: Alternator Replacement | M23: 500 | N23: 900 | O23: 1.5 | P23: 3 | Q23: 1
A24: 23 | B24: jar | C24: Inferno | D24: =CHAR(RANDBETWEEN(65,90))&CHAR(RANDBETWEEN(65,90))&CHAR(RANDBETWEEN(48,57)) -> AA5 | E24: =PROPER(B24)&" "&PROPER(C24)&" "&D24 -> Jar Inferno AA5 | K24: 23 | L24: Starter Motor Replacement | M24: 400 | N24: 700 | O24: 1.5 | P24: 2.5 | Q24: 1
A25: 24 | B25: xim | C25: Formula | D25: =CHAR(RANDBETWEEN(65,90))&CHAR(RANDBETWEEN(65,90))&CHAR(RANDBETWEEN(48,57)) -> UB4 | E25: =PROPER(B25)&" "&PROPER(C25)&" "&D25 -> Xim Formula UB4 | K25: 24 | L25: Diagnostic Check (Scan Tool) | M25: 75 | N25: 150 | O25: 0.5 | P25: 1 | Q25: 1
A26: 25 | B26: solion | C26: Essence | D26: =CHAR(RANDBETWEEN(65,90))&CHAR(RANDBETWEEN(65,90))&CHAR(RANDBETWEEN(48,57)) -> HD6 | E26: =PROPER(B26)&" "&PROPER(C26)&" "&D26 -> Solion Essence HD6 | K26: 25 | L26: O2 Sensor Replacement | M26: 200 | N26: 400 | O26: 0.5 | P26: 1.5 | Q26: 1
A27: 26 | B27: zlohook | C27: Desire | D27: =CHAR(RANDBETWEEN(65,90))&CHAR(RANDBETWEEN(65,90))&CHAR(RANDBETWEEN(48,57)) -> ET3 | E27: =PROPER(B27)&" "&PROPER(C27)&" "&D27 -> Zlohook Desire ET3 | K27: 26 | L27: Headlight Bulb Replacement (pair) | M27: 40 | N27: 150 | O27: 0.2 | P27: 0.8 | Q27: 2
A28: 27 | B28: Charish | C28: Roamer | D28: =CHAR(RANDBETWEEN(65,90))&CHAR(RANDBETWEEN(65,90))&CHAR(RANDBETWEEN(48,57)) -> VE9 | E28: =PROPER(B28)&" "&PROPER(C28)&" "&D28 -> Charish Roamer VE9 | K28: 27 | L28: Mass Air Flow (MAF) Sensor | M28: 250 | N28: 450 | O28: 0.3 | P28: 0.8 | Q28: 1
A29: 28 | B29: Biate | C29: Sliver | D29: =CHAR(RANDBETWEEN(65,90))&CHAR(RANDBETWEEN(65,90))&CHAR(RANDBETWEEN(48,57)) -> HW7 | E29: =PROPER(B29)&" "&PROPER(C29)&" "&D29 -> Biate Sliver HW7 | K29: 28 | L29: Water Pump Replacement | M29: 600 | N29: 1100 | O29: 2.5 | P29: 5 | Q29: 1
A30: 29 | B30: Carbass | C30: Tradition | D30: =CHAR(RANDBETWEEN(65,90))&CHAR(RANDBETWEEN(65,90))&CHAR(RANDBETWEEN(48,57)) -> FT8 | E30: =PROPER(B30)&" "&PROPER(C30)&" "&D30 -> Carbass Tradition FT8 | K30: 29 | L30: Radiator Replacement | M30: 500 | N30: 1000 | O30: 2 | P30: 4 | Q30: 1
A31: 30 | B31: ugeu | C31: Vision | D31: =CHAR(RANDBETWEEN(65,90))&CHAR(RANDBETWEEN(65,90))&CHAR(RANDBETWEEN(48,57)) -> KE7 | E31: =PROPER(B31)&" "&PROPER(C31)&" "&D31 -> Ugeu Vision KE7 | K31: 30 | L31: Fuel Pump Replacement | M31: 700 | N31: 1300 | O31: 2.5 | P31: 4.5 | Q31: 1
... A34: 33 | B34: gholdu | C34: Baron | D34: =CHAR(RANDBETWEEN(65,90))&CHAR(RANDBETWEEN(65,90))&CHAR(RANDBETWEEN(48,57)) -> VG8 | E34: =PROPER(B34)&" "&PROPER(C34)&" "&D34 -> Gholdu Baron VG8 | K34: 33 | L34: Catalytic Converter Replacement | M34: 1000 | N34: 3000 | O34: 1 | P34: 2.5 | Q34: 1
A35: 34 | B35: pind | C35: Serpent | D35: =CHAR(RANDBETWEEN(65,90))&CHAR(RANDBETWEEN(65,90))&CHAR(RANDBETWEEN(48,57)) -> PM2 | E35: =PROPER(B35)&" "&PROPER(C35)&" "&D35 -> Pind Serpent PM2 | K35: 34 | L35: Shocks and Struts Replacement (Pair) | M35: 600 | N35: 1200 | O35: 0.5 | P35: 2 | Q35: 2 or 4
A36: 35 | B36: teline | C36: Deputy | D36: =CHAR(RANDBETWEEN(65,90))&CHAR(RANDBETWEEN(65,90))&CHAR(RANDBETWEEN(48,57)) -> ZQ9 | E36: =PROPER(B36)&" "&PROPER(C36)&" "&D36 -> Teline Deputy ZQ9 | K36: 35 | L36: CV Axle Replacement | M36: 350 | N36: 650 | O36: 1.5 | P36: 2.5 | Q36: 1 or 2
A37: 36 | B37: vuhoom | C37: Avalanche | D37: =CHAR(RANDBETWEEN(65,90))&CHAR(RANDBETWEEN(65,90))&CHAR(RANDBETWEEN(48,57)) -> RB9 | E37: =PROPER(B37)&" "&PROPER(C37)&" "&D37 -> Vuhoom Avalanche RB9 | K37: 36 | L37: Wheel Bearing Replacement (One) | M37: 300 | N37: 500 | O37: 1.5 | P37: 2.5 | Q37: 1 to 4
A38: 37 | B38: Monooat | C38: Phantom | D38: =CHAR(RANDBETWEEN(65,90))&CHAR(RANDBETWEEN(65,90))&CHAR(RANDBETWEEN(48,57)) -> LE6 | E38: =PROPER(B38)&" "&PROPER(C38)&" "&D38 -> Monooat Phantom LE6 | K38: 37 | L38: Head Gasket Repair | M38: 2000 | N38: 4000 | O38: 10 | P38: 20 | Q38: 1
A39: 38 | B39: Resought | C39: Virtue | D39: =CHAR(RANDBETWEEN(65,90))&CHAR(RANDBETWEEN(65,90))&CHAR(RANDBETWEEN(48,57)) -> FE4 | E39: =PROPER(B39)&" "&PROPER(C39)&" "&D39 -> Resought Virtue FE4
A40: 39 | B40: Exbusm | C40: Basilisk | D40: =CHAR(RANDBETWEEN(65,90))&CHAR(RANDBETWEEN(65,90))&CHAR(RANDBETWEEN(48,57)) -> EY8 | E40: =PROPER(B40)&" "&PROPER(C40)&" "&D40 -> Exbusm Basilisk EY8
A41: 40 | B41: evle | C41: Formula | D41: =CHAR(RANDBETWEEN(65,90))&CHAR(RANDBETWEEN(65,90))&CHAR(RANDBETWEEN(48,57)) -> EM3 | E41: =PROPER(B41)&" "&PROPER(C41)&" "&D41 -> Evle Formula EM3
A42: 41 | B42: Inlter | C42: Ranger | D42: =CHAR(RANDBETWEEN(65,90))&CHAR(RANDBETWEEN(65,90))&CHAR(RANDBETWEEN(48,57)) -> HW8 | E42: =PROPER(B42)&" "&PROPER(C42)&" "&D42 -> Inlter Ranger HW8
...

Sheet Theaters
A1: Code | B1: BusinessName
A2: 1 | B2: The Watchtower Concert Hall
A3: 2 | B3: The Downtown Assembly Hall
A4: 3 | B4: The Stellar Opera House
A5: 4 | B5: The Velvet Theater
A6: 5 | B6: The Sapphire Opera House
A7: 6 | B7: The Luminus Assembly Hall
A8: 7 | B8: The Aura Theatre
A9: 8 | B9: The Melody Amphitheater
A10: 9 | B10: The Paramount Theater
A11: 10 | B11: The Century Theater
A12: 11 | B12: The Bluebell Opera House
A13: 12 | B13: The Beacon Opera House
... A51: 50 | B51: The Grand River Cinema

Sheet Courses
A1: Code | B1: Course Title
A2: 1 | B2: 2D Animation
A3: 2 | B3: Accounting Essentials
A4: 3 | B4: American Sign Language
A5: 4 | B5: Applied Math
A6: 5 | B6: Applied Mathematics
A7: 6 | B7: Band
A8: 7 | B8: Biology
A9: 8 | B9: Canada in the Contemporary World
A10: 9 | B10: Chemistry
A11: 10 | B11: Choral Music
A12: 11 | B12: Cinema as a Witness to Modern History
A13: 12 | B13: Comprehensive ELA
... A43: 42 | B43: Business Innovations

Sheet SummerJobs
A1: Code | B1: Summer Job Descriptions
A2: 1 | B2: picking berries
A3: 2 | B3: cutting grass
A4: 3 | B4: walking dogs
A5: 4 | B5: cleaning cars
A6: 5 | B6: scooping ice cream
A7: 6 | B7: waiting tables
A8: 7 | B8: washing dishes
A9: 8 | B9: stocking shelves
A10: 9 | B10: working as a cashier
A11: 10 | B11: lifeguarding at a pool
A12: 11 | B12: counseling at a camp
A13: 12 | B13: babysitting children
... A51: 50 | B51: taking food orders

Sheet Currency
A1: Code | B1: Canadian Dollar▲ | C1: 1.00 CAD▲▼ | D1: inv. 1.00 CAD▲▼ | E1: Country | F1: CurrencyCode
A2: 1 | B2: Argentine Peso | C2: 1023.8508 | D2: 0.000977 | E2: #VALUE! | F2: ARS
A3: 2 | B3: Australian Dollar | C3: 1.090257 | D3: 0.917215 | E3: #VALUE! | F3: AUD
A4: 3 | B4: Bahraini Dinar | C4: 0.268753 | D4: 3.720888 | E4: #VALUE! | F4: BHD
A5: 4 | B5: Botswana Pula | C5: 10.018072 | D5: 0.09982 | E5: #VALUE! | F5: BWP
A6: 5 | B6: Brazilian Real | C6: 3.839983 | D6: 0.260418 | E6: #VALUE! | F6: BRL
A7: 6 | B7: British Pound | C7: 0.536018 | D7: 1.86561 | E7: #VALUE! | F7: GBP
A8: 7 | B8: Bruneian Dollar | C8: 0.926707 | D8: 1.07909 | E8: #VALUE! | F8: BND
A9: 8 | B9: Bulgarian Lev | C9: 1.200356 | D9: 0.833086 | E9: #VALUE! | F9: BGN
A10: 9 | B10: Chilean Peso | C10: 672.25664 | D10: 0.001488 | E10: #VALUE! | F10: CLF
A11: 10 | B11: Chinese Yuan Renminbi | C11: 5.082304 | D11: 0.196761 | E11: #VALUE! | F11: CNY
A12: 11 | B12: Colombian Peso | C12: 2748.3651 | D12: 0.000364 | E12: #VALUE! | F12: COP
A13: 12 | B13: Czech Koruna | C13: 14.927339 | D13: 0.066991 | E13: #VALUE! | F13: CZK
... A52: 51 | B52: US Dollar | C52: 0.714769 | D52: 1.399054 | E52: #VALUE! | F52: USD

Sheet PlacesCDN
A1: Code | B1: City | C1: Province/Territory | D1: Population (2021) | E1: Average July Temp (°C) | F1: Avg. Monthly Precip. (mm) | G1: Abbr | H1: FullName
A2: 1 | B2: Edmonton | C2: Alberta | D2: 1010899 | E2: 17.7 | F2: 78 | G2: AB | H2: =PlacesCDN!$B2&", "&PlacesCDN!$C2 -> Edmonton, Alberta
A3: 2 | B3: Calgary | C3: Alberta | D3: 1306784 | E3: 16.5 | F3: 55 | G3: AB | H3: =PlacesCDN!$B3&", "&PlacesCDN!$C3 -> Calgary, Alberta
A4: 3 | B4: Banff | C4: Alberta | D4: 8305 | E4: 14.8 | F4: 51 | G4: AB | H4: =PlacesCDN!$B4&", "&PlacesCDN!$C4 -> Banff, Alberta
A5: 4 | B5: Jasper | C5: Alberta | D5: 4738 | E5: 15.6 | F5: 50 | G5: AB | H5: =PlacesCDN!$B5&", "&PlacesCDN!$C5 -> Jasper, Alberta
A6: 5 | B6: Lethbridge | C6: Alberta | D6: 98406 | E6: 18.6 | F6: 54 | G6: AB | H6: =PlacesCDN!$B6&", "&PlacesCDN!$C6 -> Lethbridge, Alberta
A7: 6 | B7: Red Deer | C7: Alberta | D7: 100844 | E7: 16.9 | F7: 80 | G7: AB | H7: =PlacesCDN!$B7&", "&PlacesCDN!$C7 -> Red Deer, Alberta
A8: 7 | B8: Medicine Hat | C8: Alberta | D8: 63271 | E8: 19.9 | F8: 52 | G8: AB | H8: =PlacesCDN!$B8&", "&PlacesCDN!$C8 -> Medicine Hat, Alberta
A9: 8 | B9: Fort McMurray | C9: Alberta | D9: 67123 | E9: 17 | F9: 70 | G9: AB | H9: =PlacesCDN!$B9&", "&PlacesCDN!$C9 -> Fort McMurray, Alberta
A10: 9 | B10: Canmore | C10: Alberta | D10: 13077 | E10: 15.5 | F10: 61 | G10: AB | H10: =PlacesCDN!$B10&", "&PlacesCDN!$C10 -> Canmore, Alberta
A11: 10 | B11: Drumheller | C11: Alberta | D11: 7909 | E11: 18.9 | F11: 60 | G11: AB | H11: =PlacesCDN!$B11&", "&PlacesCDN!$C11 -> Drumheller, Alberta
A12: 11 | B12: Grande Prairie | C12: Alberta | D12: 64141 | E12: 16.2 | F12: 64 | G12: AB | H12: =PlacesCDN!$B12&", "&PlacesCDN!$C12 -> Grande Prairie, Alberta
A13: 12 | B13: Brooks | C13: Alberta | D13: 14924 | E13: 18.9 | F13: 50 | G13: AB | H13: =PlacesCDN!$B13&", "&PlacesCDN!$C13 -> Brooks, Alberta
... A99: 98 | B99: Carcross | C99: Yukon | D99: 317 | E99: 14 | F99: 23 | G99: YK | H99: =PlacesCDN!$B99&", "&PlacesCDN!$C99 -> Carcross, Yukon

Sheet PlacesGLOBAL
A1: Code | B1: City | C1: Nation | D1: Population
A2: 1 | B2: Baghdad | C2: Iraq | D2: 6811955
A3: 2 | B3: Bangkok | C3: Thailand | D3: 10156316
A4: 3 | B4: Beijing | C4: China | D4: 19617963
A5: 4 | B5: Bogotá | C5: Colombia | D5: 10574409
A6: 5 | B6: Buenos Aires | C6: Argentina | D6: 14966530
A7: 6 | B7: Cairo | C7: Egypt | D7: 20076002
A8: 7 | B8: Dhaka | C8: Bangladesh | D8: 19578421
A9: 8 | B9: Jakarta | C9: Indonesia | D9: 10516927
A10: 9 | B10: Khartoum | C10: Sudan | D10: 5534079
A11: 10 | B11: Kinshasa | C11: DR Congo | D11: 13171256
A12: 11 | B12: Kuala Lumpur | C12: Malaysia | D12: 7563912
A13: 12 | B13: Lima | C13: Peru | D13: 10390607
... A26: 25 | B26: Tokyo | C26: Japan | D26: 37468302

Sheet Sandwiches
A1: Code | B1: Sandwiches
A2: 1 | B2: Avocado Toast Sandwiches
A3: 2 | B3: Bacon Cheeseburgers
A4: 3 | B4: Bacon, Lettuce and Tomato Sandwiches
A5: 4 | B5: Banh Mi Sandwiches
A6: 5 | B6: BBQ Burgers
A7: 6 | B7: Bison Burgers
A8: 7 | B8: Black Bean Burgers
A9: 8 | B9: BLT Sandwiches
A10: 9 | B10: California Burgers
A11: 10 | B11: Caprese Sandwiches
A12: 11 | B12: Carolina Burgers
A13: 12 | B13: Chickpea Salad
... A52: 51 | B52: Veggie Sandwiches

Sheet ImprovementLevies
A1: Code | B1: IMPROVEMENT | C1: TERMYEARS | D1: LEVYFRONTAGEFOOT | E1: Low | F1: High
A2: 1 | B2: Asphalt Surface Roadways | C2: 10 | D2: 54.35 | E2: 50 | F2: 60
A3: 2 | B3: Boulevards | C3: 3 | D3: 29.79 | E3: 25 | F3: 35
A4: 3 | B4: Concrete Lane Pavement | C4: 20 | D4: 37.365 | E4: 30 | F4: 40
A5: 4 | B5: Concrete Sidewalk | C5: 5 | D5: 24.165 | E5: 20 | F5: 30
A6: 5 | B6: Concrete Street Pavement | C6: 10 | D6: 93.75 | E6: 85 | F6: 110
A7: 6 | B7: Granular Surface Lanes | C7: 3 | D7: 26.07 | E7: 20 | F7: 30
A8: 7 | B8: Lane Lighting on Wood Poles | C8: 3 | D8: 1.86 | E8: 1 | F8: 8
A9: 8 | B9: Lane Oiling | C9: 1 | D9: 17.5 | E9: 10 | F9: 25
A10: 9 | B10: Ornamental Lights Lane | C10: 3 | D10: 11.17 | E10: 7 | F10: 22
A11: 10 | B11: Ornamental Lights Street | C11: 3 | D11: 14.9 | E11: 8 | F11: 29
A12: 11 | B12: Road Oiling | C12: 1 | D12: 16 | E12: 10 | F12: 25
A13: 12 | B13: Wastewater Sewers | C13: 20 | D13: 16.1 | E13: 10 | F13: 25
A14: 13 | B14: Watermains | C14: 10 | D14: 22.42 | E14: 15 | F14: 35

Sheet MultipleChoiceTemplate

Sheet Businesses
A1: Code | B1: BusinessName
A2: 104 | B2: Abernathy's
A3: 87 | B3: Adler & Frost
A4: 132 | B4: Apex & Co.
A5: 10 | B5: Arcane Cloud
A6: 71 | B6: Ashworth & Browne
A7: 159 | B7: Aura
A8: 105 | B8: Bainbridge's
A9: 81 | B9: Barrow & Kent
A10: 142 | B10: Bayside Traders
A11: 86 | B11: Beaumont & Crest
A12: 74 | B12: Beckett & Thorne
A13: 33 | B13: Beedle Microsystems
... A171: 126 | B171: Zenith Goods
